Workbook

Sheet Demo
A1: AtliQ Contract Risk Analyzer: running cost as built (demo)
A4: Inputs | B4: Value | E4: Source / note
A5: Contracts reviewed per month (today) | B5: 20 | E5: Assumption from AtliQ_Cost_Estimation.md (§1): ~20 contracts a month today.
A6: Contracts reviewed per month (10× growth) | B6: 200 | E6: Scale scenario used in AtliQ_Cost_Estimation.md.
A7: Review runs per contract (re-runs on new drafts) | B7: 1.5 | E7: Assumption from AtliQ_Cost_Estimation.md (§3): new drafts during negotiation get re-reviewed.
A8: Reading time per contract without the tool (hours) | B8: 3 | E8: From the AI Opportunity Map and cost doc: every contract is a fresh ~3-hour read.
A10: Claude Haiku 5.5 price | B10: $ per 1M tokens | E10: Source / note
A11: Input (not cached) | B11: 0.1 | E11: Vendor list rate (USD / 1M tokens): https://platform.claude.com/docs/en/models/haiku-5-5/overview
A12: Cache write (5-minute) | B12: 0.125 | E12: 1.25 × input price, Anthropic prompt-caching pricing.
A13: Cache read | B13: 0.01 | E13: 0.1 × input price, Anthropic prompt-caching pricing.
A14: Output | B14: 0.5 | E14: Vendor list rate (USD / 1M tokens): https://platform.claude.com/docs/en/models/haiku-5-5/overview
A16: Tokens per review (measured) | B16: Tokens | C16: Cost per review | D16: How it's calculated | E16: Source / note
A17: Input (not cached) | B17: 200 | C17: =B17*B11/1000000 | D17: Tokens × price per 1M ÷ 1,000,000 → B17 × B11 ÷ 1,000,000 | E17: Average of the 15 Claude reviews in the golden-set eval run (13 Oct 2026), as reported by the Anthropic API.
A18: Cache write | B18: 5000 | C18: =B18*B12/1000000 | D18: Tokens × price per 1M ÷ 1,000,000 → B18 × B12 ÷ 1,000,000
A19: Cache read | B19: 7000 | C19: =B19*B13/1000000 | D19: Tokens × price per 1M ÷ 1,000,000 → B19 × B13 ÷ 1,000,000
A20: Output | B20: 15000 | C20: =B20*B14/1000000 | D20: Tokens × price per 1M ÷ 1,000,000 → B20 × B14 ÷ 1,000,000
A21: Claude cost per review | C21: =SUM(C17:C20) | D21: Add the four token costs → C17 + C18 + C19 + C20 | E21: The rules engine is free; Claude only adds a second opinion.
A23: Monthly running cost | B23: Today | C23: 10× growth | D23: How it's calculated | E23: Note
A24: Reviews run per month | B24: =B5*B7 | C24: =B6*B7 | D24: Contracts per month × runs per contract → Today: B5 × B7 · 10×: B6 × B7
A25: Claude API (Haiku 5.5) | B25: =B24*$C$21 | C25: =C24*$C$21 | D25: Reviews per month × Claude cost per review → Today: B24 × C21 · 10×: C24 × C21
A26: Rules engine | B26: 0 | C26: 0 | D26: Fixed amount you enter (input) | E26: Runs inside the app; no external service.
A27: Database (SQLite file) | B27: 0 | C27: 0 | D27: Fixed amount you enter (input) | E27: A local file; no database server.
A28: Hosting | B28: 0 | C28: 0 | D28: Fixed amount you enter (input) | E28: Runs on your computer today. Enter a monthly hosting price here if you put it online.
A29: Total per month | B29: =SUM(B25:B28) | C29: =SUM(C25:C28) | D29: Add every monthly cost above → Today: B25 + B26 + B27 + B28 · 10×: C25 + C26 + C27 + C28
A30: Total per year | B30: =B29*12 | C30: =C29*12 | D30: Monthly total × 12 months → Today: B29 × 12 · 10×: C29 × 12
A32: What it saves | B32: Today | C32: 10× growth | D32: How it's calculated | E32: Note
A33: Baseline manual reading workload (hours/month) | B33: =B5*B8 | C33: =B6*B8 | D33: Contracts per month × reading hours per contract → Today: B5 × B8 · 10×: B6 × B8 | E33: Baseline, not realized time saved. Net savings require demonstrated human verification times and production-quality output.
A34: Haiku API cost / baseline reading hour (not ROI) | B34: =IF(B33=0,0,B25/B33) | C34: =IF(C33=0,0,C25/C33) | D34: Claude cost per month ÷ hours saved per month (0 if no hours) → Today: B25 ÷ B33 · 10×: C25 ÷ C33 | E34: API-only ratio, not all-in cost or ROI. Excludes validation, support, hosting and implementation.
A36: One-off costs | B36: Cost | D36: How it's calculated | E36: Note
A37: One full accuracy check (15 drafts, with Claude) | B37: =15*C21 | D37: 15 draft contracts × Claude cost per review → 15 × C21 | E37: Re-run after changing rules or prompts. The rules-only check is free.
A39: Notes
A40: • Measured cost varies by contract length: in the eval run, Claude's output ranged from 6,272 to 20,669 tokens per review.
A41: • Prices are Anthropic's list prices for Claude Haiku 5.5 on prompts up to 100K tokens; longer prompts cost 5× more ($0.50 in / $2.50 out per 1M).
A42: • Without an API key the app uses the free rules engine only, and the monthly cost is $0.
A44: Human review: conditional planning scenario | B44: Today | C44: 10× growth | D44: How it's calculated | E44: Assumption / limitation
A45: Assisted human minutes per contract | B45: =Production!$B$49 | C45: =B45 | D45: Linked to the Production scenario's contract mix. | E45: Not measured. Demo alone is NOT a safe production-quality replacement.
A46: Conditional net human hours freed/month | B46: =B5*MAX(0,B8-B45/60) | C46: =B6*MAX(0,B8-C45/60) | D46: Volume × (baseline hours - manual validation hours). | E46: Illustrative opportunity capacity only, conditional on acceptable quality.
A47: Haiku cost / conditional net hour | B47: =IF(B46>0,B25/B46,0) | C47: =IF(C46>0,C25/C46,0) | D47: Haiku API cost divided by net conditional review hours. | E47: Not all-in operating cost and not actual ROI.
A48: • Demo measures rules + Haiku API costs only; the full PRD requires human approval, retrieval, citations, quality gates and security.

Sheet Production
A1: AtliQ Contract Risk Analyzer: production plan (itemized estimate)
A2: Same format as original: Opus + Haiku, Voyage, Textract, managed Postgres, AWS and SSO. Production inputs below are planning assumptions, not measured quotes.
A4: Monthly running cost | B4: Today: low | C4: Today: high | D4: 10×: low | E4: 10×: high | F4: Source / how it's calculated
A5: Claude models (Opus 5.5 + Haiku 5.5) | B5: =B37 | C5: =B37 | D5: =D37 | E5: =D37 | F5: Formula: incoming contracts × review runs × weighted Opus+Haiku cost; includes retry allowance. See rows 19–37.
A6: Embeddings + OCR | B6: =B58 | C6: =B58 | D6: =D58 | E6: =D58 | F6: Formula: weighted scanned pages × Textract rate + pages × embedding rate, multiplied by review runs. See rows 40–58.
A7: Infrastructure (hosting, database, storage, monitoring) | B7: =B69 | C7: =C69 | D7: =D69 | E7: =E69 | F7: Itemized low/high cloud budgets (not vendor quotes) by service in rows 61–69.
A8: Total per month | B8: =SUM(B5:B7) | C8: =SUM(C5:C7) | D8: =SUM(D5:D7) | E8: =SUM(E5:E7) | F8: Add the three cost rows above, in each column → e.g. Today low: B5 + B6 + B7
A9: Total per year | B9: =B8*12 | C9: =C8*12 | D9: =D8*12 | E9: =E8*12 | F9: Monthly total × 12 months → e.g. Today low: B8 × 12
A11: Compared with the demo | B11: Today | D11: 10× growth | F11: How it's calculated
A12: Demo total per month | B12: =Demo!B29 | D12: =Demo!C29 | F12: Copied from the Demo tab's monthly total → Today: Demo!B29 · 10×: Demo!C29
A13: Production total per month (midpoint) | B13: =(B8+C8)/2 | D13: =(D8+E8)/2 | F13: Production platform midpoint (excludes recurring support). For ALL-IN cost and ROI see rows 80–85.
A15: • Budgeted production costs use auditable model/token/document assumptions; all-in costs also include recurring support.
A16: • Reviewer time released is opportunity capacity, not guaranteed cash savings. Confirm in shadow-mode testing and obtain vendor quotes.
A18: 01 | PRODUCTION USAGE & MODEL WORKLOAD
A19: Incoming contracts / month | B19: =Demo!B5 | D19: =Demo!B6 | F19: 20 per month from PRD; 200 is a capacity scenario.
A20: Review runs per incoming contract | B20: =Demo!B7 | D20: =B20 | F20: Revisions / redrafts; planning assumption.
A21: Retries and extra inference allowance | B21: 0.1 | F21: Unverified 10% planning allowance, before audit.
A22: Haiku API per call (USD) | B22: =Demo!C21 | F22: Demo!C21 measured 15-run average, subject to API billing validation.
A23: Opus 5.5 input USD / 1M tokens | B23: 4 | F23: https://platform.claude.com/docs/en/models/opus-5-5/overview
A24: Opus 5.5 cache write USD / 1M | B24: 5 | F24: 5-minute cache pricing; same vendor URL.
A25: Opus 5.5 cache read USD / 1M | B25: 0.2 | F25: Same vendor URL.
A26: Opus 5.5 output USD / 1M tokens | B26: 20 | F26: Same vendor URL; long-context tier may cost more.
A27: Opus uncached input tokens / call | B27: 50000 | F27: Planning hypothesis, not telemetry.
A28: Opus cache write tokens / call | B28: 0 | F28: Planning hypothesis; model changes if caching is enabled.
A29: Opus cache read tokens / call | B29: 0 | F29: Planning hypothesis; model changes if caching is enabled.
A30: Opus output tokens / call | B30: 20000 | F30: Planning hypothesis including reasoning; verify.
A31: Opus calls / review run | B31: 2 | F31: Compare and evidence-check; needs architecture trace.
A32: Haiku calls / review run | B32: 1 | F32: Measured profile reused as one extraction call.
A33: Calculated Opus cost / call | B33: =(B27*B23+B28*B24+B29*B25+B30*B26)/1000000
A34: Calculated models cost / run BEFORE retries | B34: =B33*B31+B22*B32
A35: Calculated models cost / run AFTER retries | B35: =B34*(1+B21)
A36: Weighted model usage factor | B36: =SUMPRODUCT(D40:D42,E40:E42)
A37: Model monthly cost (today / 10×) | B37: =B19*B20*B35*B36 | D37: =D19*D20*B35*B36 | F37: Volume × review runs × cost / run × contract complexity mix.
A38: 02 | CONTRACT TYPE MIX & DOCUMENT PROFILES
A39: Contract type | B39: Pages / doc | C39: Scan ratio | D39: Model factor | E39: Portfolio mix | F39: Mix, lengths and scan shares are planning assumptions.
A40: Short NDA | B40: 10 | C40: 0.1 | D40: 0.5 | E40: 0.25 | F40: Shorter model context and less manual checking.
A41: Typical MSA / SOW | B41: 25 | C41: 0.25 | D41: 1 | E41: 0.6 | F41: Base model token profile.
A42: Long / complex | B42: 75 | C42: 0.6 | D42: 3 | E42: 0.15 | F42: Longer prompts and clauses cost ~3×; verify.
A43: Total contract mix | E43: =SUM(E40:E42) | F43: Must equal 100%; update short/typical/long shares.
A44: Weighted average pages / contract | B44: =SUMPRODUCT(B40:B42,E40:E42)
...
